Давайте изучим следующий код:

#include <stdexcept>

extern bool X;

struct MyError : std::runtime_error
{
    MyError(char const* s) 
        : std::runtime_error(s)
    {
        if (X)
            throw std::logic_error("Logic error");
    }
};

void foo()
{
    throw MyError("My error");
}

Отметьте верные утверждения.

 Если при вызове foo() X = true, то произойдёт аварийное завершение программы.
 +Если при вызове foo() X = true, то за пределы функции foo будет выброшено исключение std::logic_error.
 Если при вызове foo() X = true, то за пределы функции foo будет выброшено исключение MyError.
 +Если при вызове foo() X = false, то за пределы функции foo будет выброшено исключение MyError.
 +Если при вызове foo() X = true, то будет вызван деструктор std::runtime_error.
 Если при вызове foo() X = true, то будет вызван деструктор MyError.
